2025-03-25 06:08:31,915 - DEBUG - Requesting weather data for coordinates: lat=-31.9505, lon=115.8605
2025-03-25 06:08:31,917 - DEBUG - Starting new HTTPS connection (1): api.openweathermap.org:443
2025-03-25 06:08:32,093 - DEBUG - https://api.openweathermap.org:443 "GET /data/2.5/weather?lat=-31.9505&lon=115.8605&appid=sdekjfbxwv;askdbn&units=metric HTTP/1.1" 401 108
2025-03-25 06:08:32,094 - ERROR - HTTP error occurred: 401 Client Error: Unauthorized for url: https://api.openweathermap.org/data/2.5/weather?lat=-31.9505&lon=115.8605&appid=sdekjfbxwv;askdbn&units=metric
2025-03-25 06:08:32,094 - ERROR - Traceback (most recent call last):
  File "C:\Users\chasi\source\repos\civ-ipos-sessions\week7\in-class-demos\debugging\4_api_logging.py", line 16, in get_weather
    response.raise_for_status()  # Raises an HTTPError for bad responses
    ~~~~~~~~~~~~~~~~~~~~~~~~~^^
  File "C:\Users\chasi\source\repos\civ-ipos-sessions\week7\.venv\Lib\site-packages\requests\models.py", line 1024, in raise_for_status
    raise HTTPError(http_error_msg, response=self)
requests.exceptions.HTTPError: 401 Client Error: Unauthorized for url: https://api.openweathermap.org/data/2.5/weather?lat=-31.9505&lon=115.8605&appid=sdekjfbxwv;askdbn&units=metric

2025-03-25 06:09:26,154 - DEBUG - Requesting weather data for coordinates: lat=-31.9505, lon=115.8605
2025-03-25 06:09:26,155 - DEBUG - Starting new HTTPS connection (1): api.openweathermap.org:443
2025-03-25 06:09:26,335 - DEBUG - https://api.openweathermap.org:443 "GET /data/2.5/weather?lat=-31.9505&lon=115.8605&appid=7761a681&units=metric HTTP/1.1" 401 108
2025-03-25 06:09:26,335 - ERROR - HTTP error occurred: 401 Client Error: Unauthorized for url: https://api.openweathermap.org/data/2.5/weather?lat=-31.9505&lon=115.8605&appid=7761a681&units=metric
2025-03-25 06:09:26,336 - ERROR - Traceback (most recent call last):
  File "C:\Users\chasi\source\repos\civ-ipos-sessions\week7\in-class-demos\debugging\4_api_logging.py", line 16, in get_weather
    response.raise_for_status()  # Raises an HTTPError for bad responses
    ~~~~~~~~~~~~~~~~~~~~~~~~~^^
  File "C:\Users\chasi\source\repos\civ-ipos-sessions\week7\.venv\Lib\site-packages\requests\models.py", line 1024, in raise_for_status
    raise HTTPError(http_error_msg, response=self)
requests.exceptions.HTTPError: 401 Client Error: Unauthorized for url: https://api.openweathermap.org/data/2.5/weather?lat=-31.9505&lon=115.8605&appid=7761a681&units=metric

